Workbook

Sheet ReadMe_File

Sheet # Databases
A1: Database Screening | B1: # Studies Identified | C1: # 1st Filter | D1: # 2nd Filter duplicattion | E1: # Studies Pass Eligibility Assessment | F1: # Studies Included
A2: IEEE Xplore | B2: =COUNTIF('1 Identification'!$A$2:$A$428,$A2) -> 78 | C2: =COUNTIF('2 Screening'!$A$2:$A$173,$A2) -> 27 | D2: =COUNTIF('3 Eligibility'!$A$2:$A$142,$A2) -> 26 | E2: =COUNTIFS('3 Eligibility'!$T$2:$T$142,">=3.5", '3 Eligibility'!$A$2:$A$142,$A2) -> 13 | F2: =COUNTIF('4 Included'!$A$2:$A$52,$A2) -> 8
A3: Scopus | B3: =COUNTIF('1 Identification'!$A$2:$A$428,$A3) -> 150 | C3: =COUNTIF('2 Screening'!$A$2:$A$173,$A3) -> 44 | D3: =COUNTIF('3 Eligibility'!$A$2:$A$142,$A3) -> 25 | E3: =COUNTIFS('3 Eligibility'!$T$2:$T$142,">=3.5", '3 Eligibility'!$A$2:$A$142,$A3) -> 12 | F3: =COUNTIF('4 Included'!$A$2:$A$52,$A3) -> 20
A4: ScienceDirect | B4: =COUNTIF('1 Identification'!$A$2:$A$428,$A4) -> 36 | C4: =COUNTIF('2 Screening'!$A$2:$A$173,$A4) -> 21 | D4: =COUNTIF('3 Eligibility'!$A$2:$A$142,$A4) -> 21 | E4: =COUNTIFS('3 Eligibility'!$T$2:$T$142,">=3.5", '3 Eligibility'!$A$2:$A$142,$A4) -> 8 | F4: =COUNTIF('4 Included'!$A$2:$A$52,$A4) -> 10
A5: Web of Science | B5: =COUNTIF('1 Identification'!$A$2:$A$428,$A5) -> 163 | C5: =COUNTIF('2 Screening'!$A$2:$A$173,$A5) -> 80 | D5: =COUNTIF('3 Eligibility'!$A$2:$A$142,$A5) -> 68 | E5: =COUNTIFS('3 Eligibility'!$T$2:$T$142,">=3.5", '3 Eligibility'!$A$2:$A$142,$A5) -> 18 | F5: =COUNTIF('4 Included'!$A$2:$A$52,$A5) -> 13
A6: Total | B6: =SUM(B2:B5) -> 427 | C6: =SUM(C2:C5) -> 172 | D6: =SUM(D2:D5) -> 140 | E6: =SUM(E2:E5) -> 51 | F6: =SUM(F2:F5) -> 51

Sheet #Publisher
A1: Publisher | B1: # of papers identified
A2: IEEE | B2: =COUNTIF('4 Included'!$D$2:$E$52,$A2) -> 22
A3: Elsevier | B3: =COUNTIF('4 Included'!$D$2:$E$52,$A3) -> 11
A4: Springer | B4: =COUNTIF('4 Included'!$D$2:$E$52,$A4) -> 6
A5: MDPI | B5: =COUNTIF('4 Included'!$D$2:$E$52,$A5) -> 5
A6: SPIE | B6: =COUNTIF('4 Included'!$D$2:$E$52,$A6) -> 2
A7: CRC Press | B7: =COUNTIF('4 Included'!$D$2:$E$52,$A7) -> 1
A8: Wiley | B8: =COUNTIF('4 Included'!$D$2:$E$52,$A8) -> 1
A9: Maruzen | B9: =COUNTIF('4 Included'!$D$2:$E$52,$A9) -> 1
A10: PeerJ | B10: =COUNTIF('4 Included'!$D$2:$E$52,$A10) -> 1
A11: IIETA | B11: =COUNTIF('4 Included'!$D$2:$E$52,$A11) -> 1
A12: Total | B12: =SUM(B2:B11) -> 51

Sheet # Reference Type
A1: Reference Type | B1: # of papers
A2: Journal Article | B2: =COUNTIF('4 Included'!$D$2:$D$52,$A2) -> 27
A3: Conference Proceedings | B3: =COUNTIF('4 Included'!$D$2:$D$52,$A3) -> 23
A4: Book Section | B4: =COUNTIF('4 Included'!$D$2:$D$52,$A4) -> 1
A5: Total | B5: =SUM(B2:B4) -> 51

Sheet # Years
A1: Year | B1: # of papers identified | C1: # of papers included
A2: 2020 | B2: =COUNTIF('1 Identification'!$D$2:$D$428,$A2) -> 15 | C2: =COUNTIF('4 Included'!$C$2:$C$52,$A2) -> 3
A3: 2021 | B3: =COUNTIF('1 Identification'!$D$2:$D$428,$A3) -> 66 | C3: =COUNTIF('4 Included'!$C$2:$C$52,$A3) -> 10
A4: 2022 | B4: =COUNTIF('1 Identification'!$D$2:$D$428,$A4) -> 148 | C4: =COUNTIF('4 Included'!$C$2:$C$52,$A4) -> 15
A5: 2023 | B5: =COUNTIF('1 Identification'!$D$2:$D$428,$A5) -> 175 | C5: =COUNTIF('4 Included'!$C$2:$C$52,$A5) -> 20
A6: 2024 | B6: =COUNTIF('1 Identification'!$D$2:$D$428,$A6) -> 23 | C6: =COUNTIF('4 Included'!$C$2:$C$52,$A6) -> 3
A7: Total | B7: =SUM(B2:B6) -> 427 | C7: =SUM(C2:C6) -> 51

Sheet # E&QA
A1: Score | B1: # of papers
A2: 0 | B2: =COUNTIF('3 Eligibility'!$T$2:$T$142,$A2) -> 0
A3: 0.5 | B3: =COUNTIF('3 Eligibility'!$T$2:$T$142,$A3) -> 3
A4: 1 | B4: =COUNTIF('3 Eligibility'!$T$2:$T$142,$A4) -> 5
A5: 1.5 | B5: =COUNTIF('3 Eligibility'!$T$2:$T$142,$A5) -> 38
A6: 2 | B6: =COUNTIF('3 Eligibility'!$T$2:$T$142,$A6) -> 28
A7: 2.5 | B7: =COUNTIF('3 Eligibility'!$T$2:$T$142,$A7) -> 10
A8: 3 | B8: =COUNTIF('3 Eligibility'!$T$2:$T$142,$A8) -> 5
A9: 3.5 | B9: =COUNTIF('3 Eligibility'!$T$2:$T$142,$A9) -> 15
A10: 4 | B10: =COUNTIF('3 Eligibility'!$T$2:$T$142,$A10) -> 37
A11: Total | B11: =SUM(B2:B10) -> 141

Sheet Techniques
A1: Parent | B1: Child | C1: #Parent | D1: #Child
A2: |AlexNet| | B2: |AlexNet| | C2: =D2 -> 2 | D2: {=SUMPRODUCT(--(ISNUMBER(SEARCH($B2,'4 Included'!$P$2:$P$52))))} -> 2
A3: |CHS-Net| | B3: |CHS-Net| | C3: =D3 -> 1 | D3: {=SUMPRODUCT(--(ISNUMBER(SEARCH($B3,'4 Included'!$P$2:$P$52))))} -> 1
A4: |CNN| | B4: |CNN| | C4: =D4 -> 23 | D4: {=SUMPRODUCT(--(ISNUMBER(SEARCH($B4,'4 Included'!$P$2:$P$52))))} -> 23
A5: |DCNN| | B5: |DCNN| | C5: =D5 -> 1 | D5: {=SUMPRODUCT(--(ISNUMBER(SEARCH($B5,'4 Included'!$P$2:$P$52))))} -> 1
A6: |DenseNet| | B6: |DenseNet| | C6: =SUM(D6:D9) -> 11 | D6: {=SUMPRODUCT(--(ISNUMBER(SEARCH($B6,'4 Included'!$P$2:$P$52))))} -> 1
B7: |DenseNet-121| | D7: {=SUMPRODUCT(--(ISNUMBER(SEARCH($B7,'4 Included'!$P$2:$P$52))))} -> 5
B8: |DenseNet-169| | D8: {=SUMPRODUCT(--(ISNUMBER(SEARCH($B8,'4 Included'!$P$2:$P$52))))} -> 3
B9: |DenseNet-201| | D9: {=SUMPRODUCT(--(ISNUMBER(SEARCH($B9,'4 Included'!$P$2:$P$52))))} -> 2
A10: |DINO| | B10: |DINO-v2| | C10: =D10 -> 1 | D10: {=SUMPRODUCT(--(ISNUMBER(SEARCH($B10,'4 Included'!$P$2:$P$52))))} -> 1
A11: |DLMs| | B11: |DLMs| | C11: =D11 -> 1 | D11: {=SUMPRODUCT(--(ISNUMBER(SEARCH($B11,'4 Included'!$P$2:$P$52))))} -> 1
A12: |DNN| | B12: |DNN| | C12: =D12 -> 1 | D12: {=SUMPRODUCT(--(ISNUMBER(SEARCH($B12,'4 Included'!$P$2:$P$52))))} -> 1
A13: |EfficientNet| | B13: |EfficientNet| | C13: =SUM(D13:D18) -> 10 | D13: {=SUMPRODUCT(--(ISNUMBER(SEARCH($B13,'4 Included'!$P$2:$P$52))))} -> 2
B14: |EfficientNet-B3| | D14: {=SUMPRODUCT(--(ISNUMBER(SEARCH($B14,'4 Included'!$P$2:$P$52))))} -> 2
B15: |EfficientNet-B4| | D15: {=SUMPRODUCT(--(ISNUMBER(SEARCH($B15,'4 Included'!$P$2:$P$52))))} -> 1
B16: |EfficientNet-B5| | D16: {=SUMPRODUCT(--(ISNUMBER(SEARCH($B16,'4 Included'!$P$2:$P$52))))} -> 1
B17: |EfficientNet-B7| | D17: {=SUMPRODUCT(--(ISNUMBER(SEARCH($B17,'4 Included'!$P$2:$P$52))))} -> 2
B18: |EfficientNet-v2| | D18: {=SUMPRODUCT(--(ISNUMBER(SEARCH($B18,'4 Included'!$P$2:$P$52))))} -> 2
A19: |EXP-Net| | B19: |EXP-Net| | C19: =D19 -> 1 | D19: {=SUMPRODUCT(--(ISNUMBER(SEARCH($B19,'4 Included'!$P$2:$P$52))))} -> 1
A20: |GINet| | B20: |GINet| | C20: =D20 -> 1 | D20: {=SUMPRODUCT(--(ISNUMBER(SEARCH($B20,'4 Included'!$P$2:$P$52))))} -> 1
A21: |GLDCNet| | B21: |GLDCNet| | C21: =D21 -> 1 | D21: {=SUMPRODUCT(--(ISNUMBER(SEARCH($B21,'4 Included'!$P$2:$P$52))))} -> 1
A22: |GoogLeNet| | B22: |GoogLeNet| | C22: =D22 -> 1 | D22: {=SUMPRODUCT(--(ISNUMBER(SEARCH($B22,'4 Included'!$P$2:$P$52))))} -> 1
A23: |HighRes3DNet| | B23: |HighRes3DNet| | C23: =D23 -> 1 | D23: {=SUMPRODUCT(--(ISNUMBER(SEARCH($B23,'4 Included'!$P$2:$P$52))))} -> 1
A24: |Inception| | B24: |Inception| | C24: =SUM(D24:D26) -> 7 | D24: {=SUMPRODUCT(--(ISNUMBER(SEARCH($B24,'4 Included'!$P$2:$P$52))))} -> 1
B25: |Inception-v2| | D25: {=SUMPRODUCT(--(ISNUMBER(SEARCH($B25,'4 Included'!$P$2:$P$52))))} -> 1
B26: |Inception-v3| | D26: {=SUMPRODUCT(--(ISNUMBER(SEARCH($B26,'4 Included'!$P$2:$P$52))))} -> 5
A27: |LightGBM| | B27: |LightGBM| | C27: =D27 -> 1 | D27: {=SUMPRODUCT(--(ISNUMBER(SEARCH($B27,'4 Included'!$P$2:$P$52))))} -> 1
A28: |Mask R CNN| | B28: |Mask R CNN| | C28: =D28 -> 2 | D28: {=SUMPRODUCT(--(ISNUMBER(SEARCH($B28,'4 Included'!$P$2:$P$52))))} -> 2
A29: |MobileNet| | B29: |MobileNet| | C29: =SUM(D29:D31) -> 6 | D29: {=SUMPRODUCT(--(ISNUMBER(SEARCH($B29,'4 Included'!$P$2:$P$52))))} -> 2
B30: |MobileNet-v2| | D30: {=SUMPRODUCT(--(ISNUMBER(SEARCH($B30,'4 Included'!$P$2:$P$52))))} -> 2
B31: |MobileNet-v3| | D31: {=SUMPRODUCT(--(ISNUMBER(SEARCH($B31,'4 Included'!$P$2:$P$52))))} -> 2
A32: |Mosquito Net| | B32: |Mosquito Net| | C32: =D32 -> 1 | D32: {=SUMPRODUCT(--(ISNUMBER(SEARCH($B32,'4 Included'!$P$2:$P$52))))} -> 1
A33: |PReLU-Net| | B33: |PReLU-Net| | C33: =D33 -> 1 | D33: {=SUMPRODUCT(--(ISNUMBER(SEARCH($B33,'4 Included'!$P$2:$P$52))))} -> 1
A34: |Res2Net| | B34: |Res2Net| | C34: =D34 -> 1 | D34: {=SUMPRODUCT(--(ISNUMBER(SEARCH($B34,'4 Included'!$P$2:$P$52))))} -> 1
A35: |ResNet| | B35: |ResNet| | C35: =SUM(D35:D41) -> 19 | D35: {=SUMPRODUCT(--(ISNUMBER(SEARCH($B35,'4 Included'!$P$2:$P$52))))} -> 2
B36: |ResNet-101| | D36: {=SUMPRODUCT(--(ISNUMBER(SEARCH($B36,'4 Included'!$P$2:$P$52))))} -> 3
B37: |ResNet-152v2| | D37: {=SUMPRODUCT(--(ISNUMBER(SEARCH($B37,'4 Included'!$P$2:$P$52))))} -> 1
B38: |ResNet-18| | D38: {=SUMPRODUCT(--(ISNUMBER(SEARCH($B38,'4 Included'!$P$2:$P$52))))} -> 1
B39: |ResNet-32| | D39: {=SUMPRODUCT(--(ISNUMBER(SEARCH($B39,'4 Included'!$P$2:$P$52))))} -> 1
B40: |ResNet-34| | D40: {=SUMPRODUCT(--(ISNUMBER(SEARCH($B40,'4 Included'!$P$2:$P$52))))} -> 1
...

Sheet Variations
A1: Short name | B1: # of papers
A2: |Grad-CAM| | B2: {=SUMPRODUCT(--(ISNUMBER(SEARCH($A2,'4 Included'!$Q$2:$Q$52))))} -> 38
A3: |Grad-CAM++| | B3: {=SUMPRODUCT(--(ISNUMBER(SEARCH($A3,'4 Included'!$Q$2:$Q$52))))} -> 9
A4: |Guided Grad-CAM| | B4: {=SUMPRODUCT(--(ISNUMBER(SEARCH($A4,'4 Included'!$Q$2:$Q$52))))} -> 3
A5: |LIME| | B5: {=SUMPRODUCT(--(ISNUMBER(SEARCH($A5,'4 Included'!$Q$2:$Q$52))))} -> 3
A6: |Ablation-CAM| | B6: {=SUMPRODUCT(--(ISNUMBER(SEARCH($A6,'4 Included'!$Q$2:$Q$52))))} -> 1
A7: |CAM| | B7: {=SUMPRODUCT(--(ISNUMBER(SEARCH($A7,'4 Included'!$Q$2:$Q$52))))} -> 1
A8: |DGXAINet| | B8: {=SUMPRODUCT(--(ISNUMBER(SEARCH($A8,'4 Included'!$Q$2:$Q$52))))} -> 1
A9: |EigenGrad-CAM| | B9: {=SUMPRODUCT(--(ISNUMBER(SEARCH($A9,'4 Included'!$Q$2:$Q$52))))} -> 1
A10: |FEM| | B10: {=SUMPRODUCT(--(ISNUMBER(SEARCH($A10,'4 Included'!$Q$2:$Q$52))))} -> 1
A11: |Grad-CAM-based RFS (GRFS)| | B11: {=SUMPRODUCT(--(ISNUMBER(SEARCH($A11,'4 Included'!$Q$2:$Q$52))))} -> 1
A12: |HayCAM| | B12: {=SUMPRODUCT(--(ISNUMBER(SEARCH($A12,'4 Included'!$Q$2:$Q$52))))} -> 1
A13: |LayersCAM| | B13: {=SUMPRODUCT(--(ISNUMBER(SEARCH($A13,'4 Included'!$Q$2:$Q$52))))} -> 1
... A21: |TS-CNN| | B21: {=SUMPRODUCT(--(ISNUMBER(SEARCH($A21,'4 Included'!$Q$2:$Q$52))))} -> 1

Sheet Metrics
A1: Short name | B1: # of papers
A2: Accuracy | B2: {=SUMPRODUCT(--(ISNUMBER(SEARCH($A2,'4 Included'!$R$2:$R$52))))} -> 42
A3: F1-Score | B3: {=SUMPRODUCT(--(ISNUMBER(SEARCH($A3,'4 Included'!$R$2:$R$52))))} -> 18
A4: Precision | B4: {=SUMPRODUCT(--(ISNUMBER(SEARCH($A4,'4 Included'!$R$2:$R$52))))} -> 17
A5: Recall | B5: {=SUMPRODUCT(--(ISNUMBER(SEARCH($A5,'4 Included'!$R$2:$R$52))))} -> 14
A6: AUC | B6: {=SUMPRODUCT(--(ISNUMBER(SEARCH($A6,'4 Included'!$R$2:$R$52))))} -> 11
A7: Specificity | B7: {=SUMPRODUCT(--(ISNUMBER(SEARCH($A7,'4 Included'!$R$2:$R$52))))} -> 9
A8: Sensitivity | B8: {=SUMPRODUCT(--(ISNUMBER(SEARCH($A8,'4 Included'!$R$2:$R$52))))} -> 8
A9: Loss | B9: {=SUMPRODUCT(--(ISNUMBER(SEARCH($A9,'4 Included'!$R$2:$R$52))))} -> 5
A10: Training Loss | B10: {=SUMPRODUCT(--(ISNUMBER(SEARCH($A10,'4 Included'!$R$2:$R$52))))} -> 4
A11: Cohen's Kappa | B11: {=SUMPRODUCT(--(ISNUMBER(SEARCH($A11,'4 Included'!$R$2:$R$52))))} -> 3
A12: MCC | B12: {=SUMPRODUCT(--(ISNUMBER(SEARCH($A12,'4 Included'!$R$2:$R$52))))} -> 2
A13: BA | B13: {=SUMPRODUCT(--(ISNUMBER(SEARCH($A13,'4 Included'!$R$2:$R$52))))} -> 1
... A23: Training time | B23: {=SUMPRODUCT(--(ISNUMBER(SEARCH($A23,'4 Included'!$R$2:$R$52))))} -> 1

Sheet 4 Included
A1: Database | B1: Author Name | C1: Year | D1: Type | E1: Publisher | F1: Published in | G1: Link | H1: Publication date | I1: Title | J1: DOI | K1: Paper ID | L1: Column1 | M1: Title | N1: Dataset | O1: Dataset Link | P1: Techniques | Q1: variations | R1: Metrics
A2: Scopus | B2: G. Mettivier; R. Ricciardi; A. Sarno; F. S. Maddaloni; M. Porzio; M. Staffa; S. Minelli; A. Santoro; E. Antignani; M. Masi; V. Landoni; P. Ordonez; F. Ferranti; L. Greco; S. Clemente; P. Russo | C2: 2022 | D2: Conference Proceedings | E2: SPIE | F2: 16th International Workshop on Breast Imaging (IWBI2022 | G2: https://www.scopus.com/inward/record.uri?eid=2-s2.0-85136130200&doi=10.1117%2f12.2625369&partnerID=40&md5=530e4632c3249279cb1b8bb57b46b5c2 | I2: DeepLook: A deep learning computed diagnosis support for breast tomosynthesis | J2: 10.1117/12.2625369 | M2: DeepLook: A deep learning computed diagnosis support for breast tomosynthesis | N2: Tomosynthesis datasets | O2: Private Dataset | P2: |DCNN| | Q2: |Grad-CAM| | R2: AUC, Accuracy, Precision, Sensitivity, Specificity, F1-Score, false positive rate | S2: .
A3: Web of Science | B3: R. R. Selvaraju; M. Cogswell; A. Das; R. Vedantam; D. Parikh; D. Batra | C3: 2020 | D3: Conference Proceedings | E3: IEEE | F3: 2017 IEEE International Conference on Computer Vision (ICCV) | G3: https://openaccess.thecvf.com/content_iccv_2017/html/Selvaraju_Grad-CAM_Visual_Explanations_ICCV_2017_paper.html | H3: 2020 FEB | I3: Grad-CAM: Visual Explanations from Deep Networks via Gradient-Based Localization | J3: 10.1007/s11263-019-01228-7 | K3: WOS:000511807100003 | M3: Grad-CAM: Visual Explanations from Deep Networks via Gradient-Based Localization | N3: Dataset bias | O3: https://github.com/ramprs/grad-cam/ | P3: |CNN|, |AlexNet|, |VGG|, |ResNet| | Q3: |Grad-CAM| | R3: Accuracy
A4: Scopus | B4: A. Schottl | C4: 2020 | D4: Conference Proceedings | E4: IEEE | F4: 2020 10th International Conference on Advanced Computer Information Technologies (ACIT) | G4: https://www.scopus.com/inward/record.uri?eid=2-s2.0-85094097648&doi=10.1109%2fACIT49673.2020.9208950&partnerID=40&md5=be4fbb5d5fc2235731ce20492f77e6cb | I4: A Light-weight Method to Foster the (Grad)CAM Interpretability and Explainability of Classification Networks | J4: 10.1109/ACIT49673.2020.9208950 | M4: A Light-weight Method to Foster the (Grad)CAM Interpretability and Explainability of Classification Networks | N4: PASCAL VOC 2012 datase | O4: https://paperswithcode.com/dataset/pascal-voc | P4: |ResNet-50| | Q4: |Grad-CAM| | R4: Accuracy
A5: Scopus | B5: E. Ennadifi; S. Laraba; D. Vincke; B. Mercatoris; B. Gosselin | C5: 2020 | D5: Conference Proceedings | E5: IEEE | F5: 2020 International Conference on Intelligent Systems and Computer Vision, ISCV 2020 | G5: https://www.scopus.com/inward/record.uri?eid=2-s2.0-85093829351&doi=10.1109%2fISCV49265.2020.9204258&partnerID=40&md5=69751b3ad91ceba11c9f2f6fe9420273 | I5: Wheat Diseases Classification and Localization Using Convolutional Neural Networks and Grad-CAM Visualization | J5: 10.1109/ISCV49265.2020.9204258 | M5: Wheat Diseases Classification and Localization Using Convolutional Neural Networks and Grad-CAM Visualization | N5: Proposed dataset | O5: Private Dataset | P5: |CNN|, |Mask R CNN|, |DenseNet-121| | Q5: |Grad-CAM| | R5: Accuracy, Training time | S5: .
A6: Scopus | B6: S. Kusunose; Y. Shinomiya; T. Ushiwaka; N. Maeda; Y. Hoshino | C6: 2021 | D6: Conference Proceedings | E6: IEEE | F6: 2021 5th IEEE International Conference on Cybernetics, CYBCONF 2021 | G6: https://www.scopus.com/inward/record.uri?eid=2-s2.0-85113749231&doi=10.1109%2fCYBCONF51991.2021.9464134&partnerID=40&md5=7489d6d47de8e9b798c8ca31d548912b | I6: Improving Individually Selectness for Immune Cells using Grad-CAM | J6: 10.1109/CYBCONF51991.2021.9464134 | M6: Improving Individually Selectness for Immune Cells using Grad-CAM | N6: N/A | O6: No detail provided | P6: |CNN|, |ResNet-32| | Q6: |Grad-CAM-based RFS (GRFS)| | R6: Accuracy, Precision, Recall
A7: IEEE Xplore | B7: V. K. Prasad; K. M. N. Raj; S. Muthya; R. S. Nair | C7: 2021 | D7: Conference Proceedings | E7: IEEE | F7: 2021 IEEE 9th International Conference on Healthcare Informatics (ICHI) | G7: https://ieeexplore.ieee.org/abstract/document/9565704 | H7: 9-12 Aug. 2021 | I7: Development and validation of ECG rhythm classification on a multitude of data sources using Deep Learning | J7: 10.1109/ICHI52183.2021.00026 | M7: Development and validation of ECG rhythm classification on a multitude of data sources using Deep Learning | N7: MIT-BIH ARRHYTHMIA DATASET | O7: Signal dataset | P7: |CNN|, |EfficientNet-B3| | Q7: |Grad-CAM| | R7: Specificity, Sensitivity, F1-Score, AUC
A8: Scopus | B8: M. I. Patel; S. Singla; R. A. Ali Mattathodi; S. Sharma; D. Gautam; S. R. Kundeti | C8: 2021 | D8: Conference Proceedings | E8: IEEE | F8: 2021 IEEE International Conference on Cloud Computing in Emerging Markets (CCEM) | G8: https://www.scopus.com/inward/record.uri?eid=2-s2.0-85128330243&doi=10.1109%2fCCEM53267.2021.00011&partnerID=40&md5=20beb7cb25babda5e8c0dc6a4857db72 | I8: Simulating Realistic MRI variations to Improve Deep Learning model and visual explanations using Grad-CAM | J8: 10.1109/CCEM53267.2021.00011 | M8: Simulating Realistic MRI variations to Improve Deep Learning model and visual explanations using Grad-CAM | N8: OASIS-3 dataset | O8: https://www.oasis-brains.org/ | P8: |HighRes3DNet| | Q8: |Grad-CAM| | R8: MSE Loss
A9: Scopus | B9: X. Cai; Z. Qiao; Y. Gan; J. Wu; M. Wu; H. Dong | C9: 2022 | D9: Conference Proceedings | E9: IEEE | F9: 2022 2nd International Conference on Computer Graphics, Image and Virtualization (ICCGIV) | G9: https://www.scopus.com/inward/record.uri?eid=2-s2.0-85150681687&doi=10.1109%2fICCGIV57403.2022.00024&partnerID=40&md5=7b20826697f96b5bdd0d1e8fb75ed456 | I9: Sound Event Detection on Grad­CAM method with Complex Pretrained Model | J9: 10.1109/ICCGIV57403.2022.00024 | M9: Sound Event Detection on Grad­CAM method with Complex Pretrained Model | N9: DCASE2022task4 dataset | O9: https://dcase.community/challenge2022/index | P9: |CNN| | Q9: |Grad-CAM| | R9: PSDS2
A10: IEEE Xplore | B10: J. Maximino; M. Coimbra; J. Pedrosa | C10: 2022 | D10: Conference Proceedings | E10: IEEE | F10: 2022 44th Annual International Conference of the IEEE Engineering in Medicine & Biology Society (EMBC) | G10: https://ieeexplore.ieee.org/abstract/document/9871235 | H10: 11-15 July 2022 | I10: Detection of COVID-19 in Point of Care Lung Ultrasound | J10: 10.1109/EMBC48229.2022.9871235 | M10: Detection of COVID-19 in Point of Care Lung Ultrasound | N10: POCOVID | O10: https://github.com/jannisborn/covid19_ultrasound | P10: |VGG16|, |ResNet-50|, |DenseNet-169|, |MobileNet-v2| | Q10: |Grad-CAM| | R10: Accuracy | S10: .
A11: IEEE Xplore | B11: H. Nasiri; G. Kheyroddin; M. Dorrigiv; M. Esmaeili; A. R. Nafchi; M. H. Ghorbani; P. Zarkesh-Ha | C11: 2022 | D11: Conference Proceedings | E11: IEEE | F11: 2022 IEEE World AI IoT Congress (AIIoT) | G11: https://ieeexplore.ieee.org/abstract/document/9817375 | H11: 6-9 June 2022 | I11: Classification of COVID-19 in Chest X-ray Images Using Fusion of Deep Features and LightGBM | J11: 10.1109/AIIoT54504.2022.9817375 | M11: Classification of COVID-19 in Chest X-ray Images Using Fusion of Deep Features and LightGBM | N11: ChestX-ray8 dataset | O11: https://openaccess.thecvf.com/content_cvpr_2017/html/Wang_ChestX-ray8_Hospital-Scale_Chest_CVPR_2017_paper.html | P11: |LightGBM|, |DenseNet-169|, |MobileNet| | Q11: |Grad-CAM| | R11: Sensitivity, Specificity, Precision, F1-Score, Accuracy
A12: Scopus | B12: H. E. Mohamadi; M. E. Hassouni | C12: 2023 | D12: Conference Proceedings | E12: IEEE | F12: 2023 10th International Conference on Wireless Networks and Mobile Communications (WINCOM) | G12: https://www.scopus.com/inward/record.uri?eid=2-s2.0-85179508570&doi=10.1109%2fWINCOM59760.2023.10322952&partnerID=40&md5=4c797ab7f52568c378255bb9a4450a6a | I12: Enhanced Deep Learning Explainability for COVID-19 Diagnosis from Chest X-ray Images by Fusing Texture and Shape Features | J12: 10.1109/WINCOM59760.2023.10322952 | M12: Enhanced Deep Learning Explainability for COVID-19 Diagnosis from Chest X-ray Images by Fusing Texture and Shape Features | N12: CXR images | O12: Private Dataset | P12: |CNN|, |VGG16|, |ResNet-50| | Q12: |FEM|, |Grad-CAM| | R12: Precision, Recall, F-Score, Accuracy, Training Loss
A13: IEEE Xplore | B13: R. H. Rifat; A. C. Shruti; M. Kamal; M. G. R. Alam | C13: 2023 | D13: Conference Proceedings | E13: IEEE | F13: 2023 26th International Conference on Computer and Information Technology (ICCIT) | G13: https://ieeexplore.ieee.org/abstract/document/10441001 | H13: 13-15 Dec. 2023 | I13: Privacy-Preserving Knee Osteoarthritis Classification: A Federated Learning Approach with Grad-CAM Visualization | J13: 10.1109/ICCIT60459.2023.10441001 | M13: Privacy-Preserving Knee Osteoarthritis Classification: A Federated Learning Approach with Grad-CAM Visualization | N13: Knee osteoarthritis severity grading dataset | O13: https://www.ncbi.nlm.nih.gov/pmc/articles/PMC9410095/ | P13: |DenseNet-169|, |Inception-v2|, |MobileNet-v2| | Q13: |Grad-CAM| | R13: Accuracy, Precision, Recall, F1-Score | S13: .
A14: Scopus | B14: R. Golash; U. Gupta; V. Vats; K. Sharma; K. Golash | C14: 2023 | D14: Conference Proceedings | E14: IEEE | F14: 2023 2nd International Conference on Smart Technologies for Smart Nation, SmartTechCon 2023 | G14: https://www.scopus.com/inward/record.uri?eid=2-s2.0-85184810534&doi=10.1109%2fSmartTechCon57526.2023.10391741&partnerID=40&md5=606cb96e6cc031b37632ae99b103c05f | I14: Unveiling the Opacity: Exploring Rationality and Explainability in Tomato Disease Classification | J14: 10.1109/SmartTechCon57526.2023.10391741 | M14: Unveiling the Opacity: Exploring Rationality and Explainability in Tomato Disease Classification | N14: PlantVillage dataset | O14: https://plantvillage.psu.edu/ | P14: |ResNet-101|, |EfficientNet-B7|, |Vision Transformer| | Q14: |Guided Grad-CAM| | R14: Accuracy, Training Loss
A15: IEEE Xplore | B15: W. Tan; J. Renkhoff; A. Velasquez; Z. Wang; L. Li; J. Wang; S. Niu; F. Yang; Y. Liu; H. Song | C15: 2023 | D15: Conference Proceedings | E15: IEEE | F15: 2023 IEEE International Conference on Fuzzy Systems (FUZZ) | G15: https://ieeexplore.ieee.org/abstract/document/10309766 | H15: 45239 | I15: NoiseCAM: Explainable AI for the Boundary Between Noise and Adversarial Attacks | M15: NoiseCAM: Explainable AI for the Boundary Between Noise and Adversarial Attacks | N15: ImageNet2012 dataset | O15: https://www.tensorflow.org/datasets/catalog/imagenet2012 | P15: |VGG16| | Q15: |Grad-CAM|, |NoiseCAM| | R15: Accuracy | S15: .
A16: IEEE Xplore | B16: P. V. R; U. Shanmugam | C16: 2023 | D16: Conference Proceedings | E16: IEEE | F16: 2023 Innovations in Power and Advanced Computing Technologies (i-PACT) | G16: https://ieeexplore.ieee.org/abstract/document/10434658 | H16: 8-10 Dec. 2023 | I16: Explainable AI for Medical Imaging: Advancing Transparency and Trust in Diagnostic Decision-Making | J16: 10.1109/i-PACT58649.2023.10434658 | M16: Explainable AI for Medical Imaging: Advancing Transparency and Trust in Diagnostic Decision-Making | N16: X-ray, MRI, and CT scans | O16: Private Dataset | P16: |CNN| | Q16: |Grad-CAM++| | R16: Accuracy, Precision, Recall, F1-Score | S16: .
A17: Scopus | B17: K. Jitha; P. Mohammed Waleed; K. Navas; C. M. Nihad Ahmed; C. P. Najiya Nasrin | C17: 2023 | D17: Conference Proceedings | E17: IEEE | F17: 2023 International Conference on Innovations in Engineering and Technology (ICIET) | G17: https://www.scopus.com/inward/record.uri?eid=2-s2.0-85171524411&doi=10.1109%2fICIET57285.2023.10220839&partnerID=40&md5=646ec919f0f808164e3f078f5967a741 | I17: Deep Learning and Grad-CAM for the Diagnosis of Pneumonia Based on X-Rays | J17: 10.1109/ICIET57285.2023.10220839 | M17: Deep Learning and Grad-CAM for the Diagnosis of Pneumonia Based on X-Rays | N17: Pneumonia dataset | O17: Private Dataset | P17: |CNN| | Q17: |Grad-CAM| | R17: Accuracy, Training Loss
A18: IEEE Xplore | B18: U. Rashmi; B. M. Beena; S. Ambesange | C18: 2023 | D18: Conference Proceedings | E18: IEEE | F18: 2023 International Conference on the Confluence of Advancements in Robotics, Vision and Interdisciplinary Technology Management (IC-RVITM) | G18: https://ieeexplore.ieee.org/abstract/document/10435182 | H18: 28-29 Nov. 2023 | I18: BrainCrossFed CNN Model for Alzheimer Classification using MRI data and Comparison and Benchmarking proposed model with DINOv2 and ExplainableAI using Grad-CAM | J18: 10.1109/IC-RVITM60032.2023.10435182 | M18: BrainCrossFed CNN Model for Alzheimer Classification using MRI data and Comparison and Benchmarking proposed model with DINOv2 and ExplainableAI using Grad-CAM | N18: ALZHEIMER'S DATASET | O18: No detail provided | P18: |DINO-v2|, |ResNet-101|, |DenseNet-121|, |VGG16| | Q18: |Grad-CAM| | R18: Accuracy, F1-Score, Precision, Recall
A19: Scopus | B19: A. Bhat; A. Raychowdhury | C19: 2023 | D19: Conference Proceedings | E19: IEEE | F19: AICAS 2023 - IEEE International Conference on Artificial Intelligence Circuits and Systems, Proceeding | G19: https://www.scopus.com/inward/record.uri?eid=2-s2.0-85166375420&doi=10.1109%2fAICAS57966.2023.10168594&partnerID=40&md5=b4ea125381ed9d581f927296b947793d | I19: Reducing Overhead of Feature Importance Visualization via Static Grad-CAM Computation | J19: 10.1109/AICAS57966.2023.10168594 | M19: Reducing Overhead of Feature Importance Visualization via Static Grad-CAM Computation | N19: CIFAR-10 dataset | O19: https://www.cs.toronto.edu/~kriz/cifar.html | P19: |CNN|, |ResNet-18| | Q19: |Grad-CAM| | R19: Accuracy, Latency (ms) | S19: .
A20: Scopus | B20: D. F. Collazos-Huertas; A. M. Álvarez-Meza; G. Castellanos-Dominguez | C20: 2022 | D20: Journal Article | E20: MDPI | F20: Applied Sciences (Switzerland) | G20: https://www.scopus.com/inward/record.uri?eid=2-s2.0-85124356263&doi=10.3390%2fapp12031695&partnerID=40&md5=868c6dc268f93ae37f3b4ec2ec7c25a7 | I20: Image-Based Learning Using Gradient Class Activation Maps for Enhanced Physiological Interpretability of Motor Imagery Skills | J20: 10.3390/app12031695 | L20: Journal MDPI | M20: Image-Based Learning Using Gradient Class Activation Maps for Enhanced Physiological Interpretability of Motor Imagery Skills | N20: Giga-Science | O20: https://gigadb.org/dataset/100295 | P20: |CNN| | Q20: |Grad-CAM++| | R20: Accuracy
A21: ScienceDirect | B21: M. Raju; V. P. Gopi; V. S. Anitha; A. Sherawat | C21: 2023 | D21: Journal Article | E21: Elsevier | F21: BenchCouncil Transactions on Benchmarks, Standards and Evaluations | G21: https://www.sciencedirect.com/science/article/pii/S2772485923000364 | H21: 2023 June | I21: CoviDetector: A transfer learning-based semi supervised approach to detect Covid-19 using CXR images | J21: https://doi.org/10.1016/j.tbench.2023.100119 | M21: Early diagnosis of Alzhiemer's disease using wavelet-pooling based deep convolutional neural network | N21: COVID CXR Image Dataset (Research), DLAI3 Hackathon Phase3 COVID-19 CXR Challenge, COVID-19 Radiography Database, Covid19 Detection | O21: https://www.kaggle.com/datasets/sid321axn/covid-cxr-image-dataset-research, https://www.kaggle.com/datasets/jonathanchan/dlai3-hackathon-phase3-covid19-cxr-challenge, https://www.kaggle.com/datasets/tawsifurrahman/covid19-radiography-database,https://www.kaggle.com/datasets/donjon00/covid19-detection | P21: |EfficientNet|, |DenseNet-121|, |VGG16|, |VGG19|, |Inception-v3| | Q21: |Grad-CAM| | R21: Accuracy, Precision, Recall, F1-Score | S21: .
A22: ScienceDirect | B22: D. Bajhaiya; S. Narayanan Unni | C22: 2024 | D22: Journal Article | E22: Elsevier | F22: Biomedical Signal Processing and Control | G22: https://www.sciencedirect.com/science/article/pii/S1746809424001836 | H22: 2024/07/01/ | I22: Deep learning-enabled detection and localization of gastrointestinal diseases using wireless-capsule endoscopic images | J22: https://doi.org/10.1016/j.bspc.2024.106125 | M22: Deep learning-enabled detection and localization of gastrointestinal diseases using wireless-capsule endoscopic images | N22: kvasir-capsule dataset | O22: https://osf.io/dv2ag/ | P22: |CNN|, |GINet| | Q22: |Grad-CAM|, |Guided Grad-CAM| | R22: Sensitivity, Specificity | S22: .
A23: Scopus | B23: M. S. Jamil; S. P. Banik; G. M. A. Rahaman; S. Saha | C23: 2023 | D23: Book Section | E23: CRC Press | F23: Computer Vision and Image Analysis for Industry 4.0 | G23: https://www.scopus.com/inward/record.uri?eid=2-s2.0-85161149678&partnerID=40&md5=9765291af356700831c028689b522a46 | I23: Advanced Grad-CAM++: Improved visual explanations of CNN decisions in diabetic retinopathy | M23: Advanced Grad-CAM++: Improved visual explanations of CNN decisions in diabetic retinopathy | N23: EyePacs dataset | O23: https://paperswithcode.com/dataset/kaggle-eyepacs | P23: |CNN|, |VGG16| | Q23: |Grad-CAM++| | R23: IoU
A24: ScienceDirect | B24: Y. Liu; J. Su; Z. Zheng; D. Liu; Y. Song; Y. Fang; P. Yang; B. Su | C24: 2024 | D24: Journal Article | E24: Elsevier | F24: Computers and Electronics in Agriculture | G24: https://www.sciencedirect.com/science/article/pii/S0168169924000590 | H24: 45312 | I24: GLDCNet: A novel convolutional neural network for grapevine leafroll disease recognition using UAV-based imagery | M24: GLDCNet: A novel convolutional neural network for grapevine leafroll disease recognition using UAV-based imagery | N24: QGIS | O24: https://qgis.org/en/site/ | P24: |GLDCNet| | Q24: |Grad-CAM| | R24: Recall, F1-Score, Accuracy, Precision
A25: ScienceDirect | B25: N. A. Hroub; A. N. Alsannaa; M. Alowaifeer; M. Alfarraj; E. Okafor | C25: 2024 | D25: Journal Article | E25: Elsevier | F25: COMPUTERS IN BIOLOGY AND MEDICINE | G25: https://www.sciencedirect.com/science/article/pii/S0010482524000969 | H25: 2024 MAR | I25: Explainable deep learning diagnostic system for prediction of lung disease from medical images | J25: 10.1016/j.compbiomed.2024.108012 | K25: WOS:001171926500001 | M25: Explainable deep learning diagnostic system for prediction of lung disease from medical images | N25: chest X-ray datasets | O25: https://www.kaggle.com/datasets/prashant268/chest-xray-covid19-pneumonia | P25: |ResNet-50|, |Inception-v3|, |DenseNet-201|, |EfficientNet-B7|, |MobileNet-v3| | Q25: |Grad-CAM|, |Grad-CAM++|, |EigenGrad-CAM|, |Ablation-CAM|, |Random-CAM|
A26: ScienceDirect | B26: S. Jain; A. Seal; A. Ojha; A. Yazidi; J. Bures; I. Tacheci; O. Krejcar | C26: 2021 | D26: Journal Article | E26: Elsevier | F26: Computers in Biology and Medicine | G26: https://www.sciencedirect.com/science/article/pii/S0010482521005837 | H26: 2021/10/01/ | I26: A deep CNN model for anomaly detection and localization in wireless capsule endoscopy images | J26: https://doi.org/10.1016/j.compbiomed.2021.104789 | M26: A deep CNN model for anomaly detection and localization in wireless capsule endoscopy images | N26: KID dataset | O26: https://hcup-us.ahrq.gov/db/nation/kid/kiddbdocumentation.jsp | P26: |CNN|, |WCENet| | Q26: |Grad-CAM++| | R26: Accuracy, Precision, Recall, F1-Score, AUC | S26: .
A27: Scopus | B27: J. Schneider; M. Vlachos | C27: 2023 | D27: Journal Article | E27: Springer | F27: Data Mining and Knowledge Discovery | G27: https://www.scopus.com/inward/record.uri?eid=2-s2.0-85148039931&doi=10.1007%2fs10618-023-00920-0&partnerID=40&md5=569b8404b41ca22ce4649a8f98ff3426 | I27: Reflective-net: learning from explanations | J27: 10.1007/s10618-023-00920-0 | M27: Reflective-net: learning from explanations | N27: Fashion-mnist | O27: https://github.com/zalandoresearch/fashion-mnist | P27: |CNN|, ResNet, |VGG| | Q27: |Grad-CAM| | R27: Accuracy | S27: .
A28: Web of Science | B28: B. Tasci | C28: 2023 | D28: Journal Article | E28: MDPI | F28: DIAGNOSTICS | G28: https://www.mdpi.com/2075-4418/13/5/859 | H28: 2023 MAR | I28: Attention Deep Feature Extraction from Brain MRIs in Explainable Mode: DGXAINet | J28: 10.3390/diagnostics13050859 | K28: WOS:000947696800001 | M28: Attention Deep Feature Extraction from Brain MRIs in Explainable Mode: DGXAINet | N28: Brain tumor dataset | O28: https://www.kaggle.com/datasets/sartajbhuvaji/brain-tumor-classification-mri | P28: |DenseNet-201| | Q28: |DGXAINet|, |Grad-CAM| | R28: Accuracy
A29: Web of Science | B29: M. Karki; K. Kantipudi; F. Yang; H. Yu; Y. X. J. Wang; Z. Yaniv; S. Jaeger | C29: 2022 | D29: Journal Article | E29: MDPI | F29: DIAGNOSTICS | G29: https://www.mdpi.com/2075-4418/12/1/188 | H29: 2022 JAN | I29: Generalization Challenges in Drug-Resistant Tuberculosis Detection from Chest X-rays | J29: 10.3390/diagnostics12010188 | K29: WOS:000746962500001 | M29: Generalization Challenges in Drug-Resistant Tuberculosis Detection from Chest X-rays | N29: CXR dataset | O29: https://github.com/v7labs/covid-19-xray-dataset | P29: |CNN| | Q29: |Grad-CAM| | R29: AUC, Accuracy | S29: .
A30: Web of Science | B30: S. Tummala; S. Kadry; A. Nadeem; H. T. Rauf; N. Gul | C30: 2023 | D30: Journal Article | E30: MDPI | F30: DIAGNOSTICS | G30: https://www.mdpi.com/2075-4418/13/9/1594 | H30: 2023 APR 29 | I30: An Explainable Classification Method Based on Complex Scaling in Histopathology Images for Lung and Colon Cancer | J30: 10.3390/diagnostics13091594 | K30: WOS:000986652400001 | M30: An Explainable Classification Method Based on Complex Scaling in Histopathology Images for Lung and Colon Cancer | N30: LC25000 histopathology dataset | O30: https://www.kaggle.com/datasets/andrewmvd/lung-and-colon-cancer-histopathological-images | P30: |EfficientNet-v2| | Q30: |Grad-CAM|, |saliency map| | R30: Accuracy, AUC, F1-Score, BA, MCC
A31: Scopus | B31: A. Kumar; S. B. Singh; S. C. Satapathy; M. Rout | C31: 2022 | D31: Journal Article | E31: Wiley | F31: Expert Systems | G31: https://www.scopus.com/inward/record.uri?eid=2-s2.0-85102651015&doi=10.1111%2fexsy.12695&partnerID=40&md5=489719e06db29aef5c68331216224d0b | I31: MOSQUITO-NET: A deep learning based CADx system for malaria diagnosis along with model interpretation using Grad-CAM and class activation maps | J31: 10.1111/exsy.12695 | M31: MOSQUITO-NET: A deep learning based CADx system for malaria diagnosis along with model interpretation using Grad-CAM and class activation maps | N31: Malaria dataset | O31: No detail provided | P31: |CNN|, |Mosquito Net| | Q31: |Grad-CAM| | R31: Accuracy, AUC, Sensitivity, Specificity, F1-Score, MCC | S31: .
A32: Web of Science | B32: V. Jain; O. Nankar; D. J. Jerrish; S. Gite; S. Patil; K. Kotecha | C32: 2021 | D32: Journal Article | E32: IEEE | F32: IEEE ACCESS | G32: https://ieeexplore.ieee.org/abstract/document/9611247 | H32: 2021 | I32: A Novel AI-Based System for Detection and Severity Prediction of Dementia Using MRI | J32: 10.1109/ACCESS.2021.3127394 | K32: WOS:000721988800001 | M32: A Novel AI-Based System for Detection and Severity Prediction of Dementia Using MRI | N32: Dementia dataset | O32: https://www.kaggle.com/datasets/shashwatwork/dementia-prediction-dataset | P32: |CNN|, |VGG16|, |VGG19| | Q32: |Grad-CAM| | R32: Precision, Recall, F1-Score, Accuracy | S32: .
A33: Web of Science | B33: D. Varam; R. Mitra; M. Mkadmi; R. A. Riyas; D. A. Abuhani; S. Dhou; A. Alzaatreh | C33: 2023 | D33: Journal Article | E33: IEEE | F33: IEEE ACCESS | G33: https://ieeexplore.ieee.org/abstract/document/10262261 | H33: 2023 | I33: Wireless Capsule Endoscopy Image Classification: An Explainable AI Approach | J33: 10.1109/ACCESS.2023.3319068 | K33: WOS:001081607200001 | M33: Wireless Capsule Endoscopy Image Classification: An Explainable AI Approach | N33: Kvasir-Capsule Dataset | O33: https://osf.io/dv2ag/ | P33: |Inception-v3|, |EfficientNet-v2|, |VGG16|, |VGG19|,|MobileNet-v3|, |ResNet-152v2|, | Q33: |Grad-CAM|, |Grad-CAM++|, |LayersCAM|, |LIME|, |SHAP| | S33: .
A34: Web of Science | B34: V. A. Ashwath; O. K. Sikha; R. Benitez | C34: 2023 | D34: Journal Article | E34: IEEE | F34: IEEE ACCESS | G34: https://ieeexplore.ieee.org/stamp/stamp.jsp?arnumber=10197361 | H34: 2023 | I34: TS-CNN: A Three-Tier Self-Interpretable CNN for Multi-Region Medical Image Classification | J34: 10.1109/ACCESS.2023.3299850 | K34: WOS:001041887000001 | M34: TS-CNN: A Three-Tier Self-Interpretable CNN for Multi-Region Medical Image Classification | N34: PAD-UFES-20 dataset | O34: https://github.com/sikha2552/TS-CNN-A-Three-Tier-Self-Interpretable-CNN-for-Medical-Image-Classification-Empowered-with-Post-hoc | P34: |DenseNet-121|, |Inception|, |Xception|, |ResNet-50| | Q34: |TS-CNN| | R34: Accuracy, Precision, Recall, F1-Score, AUC | S34: .
A35: Web of Science | B35: Z. Lai; L. C. Oliveira; R. Guo; W. Xu; Z. Hu; K. Mifflin; C. Decarli; S.-C. Cheung; C.-N. Chuah; B. N. Dugger | C35: 2022 | D35: Journal Article | E35: IEEE | F35: IEEE ACCESS | G35: https://ieeexplore.ieee.org/abstract/document/9766171 | H35: 2022 | I35: BrainSec: Automated Brain Tissue Segmentation Pipeline for Scalable Neuropathological Analysis | J35: 10.1109/ACCESS.2022.3171927 | K35: WOS:000797423700001 | M35: BrainSec: Automated Brain Tissue Segmentation Pipeline for Scalable Neuropathological Analysis | N35: Whole Slide Images (WSIs) dataset | O35: No detail provided | P35: |CNN| | Q35: |Grad-CAM| | R35: Accuracy | S35: .
A36: Web of Science | B36: P. X. Nguyen; H. Q. Cao; K. V. T. Nguyen; H. Nguyen; T. Yairi | C36: 2022 | D36: Journal Article | E36: Maruzen | F36: IEICE TRANSACTIONS ON INFORMATION AND SYSTEMS | G36: https://search.ieice.org/bin/summary.php?id=e105-d_8_1401 | H36: 2022 AUG | I36: SeCAM: Tightly Accelerate the Image Explanation via Region-Based Segmentation | J36: 10.1587/transinf.2021EDP7205 | K36: WOS:000836845200005 | M36: SeCAM: Tightly Accelerate the Image Explanation via Region-Based Segmentation | N36: ILSVRC-2012 | O36: No detail provided | P36: |ResNet-50|, |Inception-v3|, |VGG16| | Q36: |SeCAM| | R36: Accuracy
A37: IEEE Xplore | B37: D. E. Turan; E. Aptoula; A. Ertürk; G. Taskin | C37: 2023 | D37: Conference Proceedings | E37: IEEE | F37: IGARSS 2023 - 2023 IEEE International Geoscience and Remote Sensing Symposium | G37: https://ieeexplore.ieee.org/abstract/document/10282341 | H37: 45219 | I37: Interpreting Hyperspectral Remote Sensing Image Classification Methods Via Explainable Artificial Intelligence | J37: 10.1109/IGARSS52108.2023.10282341 | M37: Interpreting Hyperspectral Remote Sensing Image Classification Methods Via Explainable Artificial Intelligence | N37: Pavia University dataset | O37: Private Dataset | P37: |CNN| | Q37: |Grad-CAM|, |Grad-CAM++|, |Guided Backpropagation| | R37: Visual representation
A38: ScienceDirect | B38: S. Singh; P. K. Jain; N. Sharma; M. Pohit; S. Roy | C38: 2023 | D38: Journal Article | E38: Elsevier | F38: Intelligent Medicine | G38: https://www.sciencedirect.com/science/article/pii/S2667102623000414 | H38: 2023/07/01/ | I38: Atherosclerotic plaque classification in carotid ultrasound images using machine learning and explainable deep learning | J38: https://doi.org/10.1016/j.imed.2023.05.003 | M38: Atherosclerotic plaque classification in carotid ultrasound images using machine learning and explainable deep learning | N38: ultrasound images | O38: http://splab.cz/en/download/databaze/ultrasound | P38: |VGG16|, |ResNet-50|, |GoogLeNet|, |Xception|, |SqueezeNET| | Q38: |Grad-CAM| | R38: Accuracy, Sensitivity, Specificity, F1-Score, Cohen's kappa, AUC
A39: ScienceDirect | B39: G. Rani; A. Misra; V. S. Dhaka; D. Buddhi; R. K. Sharma; E. Zumpano; E. Vocaturo | C39: 2022 | D39: Journal Article | E39: Elsevier | F39: Intelligent Systems with Applications | G39: https://www.sciencedirect.com/science/article/pii/S2667305322000850 | H39: 2022/11/01/ | I39: A multi-modal bone suppression, lung segmentation, and classification approach for accurate COVID-19 detection using chest radiographs | J39: https://doi.org/10.1016/j.iswa.2022.200148 | M39: A multi-modal bone suppression, lung segmentation, and classification approach for accurate COVID-19 detection using chest radiographs | N39: COVID-Pneumonia CXR | O39: https://github.com/ieee8023/covid-chestxray-dataset | P39: |EXP-Net| | Q39: |Grad-CAM++| | R39: AUC, Cohen's kappa, F1-Score, Training Loss, Accuracy, Precision, Recall
A40: Scopus | B40: S. Park; C. Wallraven | C40: 2022 | D40: Conference Proceedings | E40: Springer | F40: Lecture Notes in Computer Science (including subseries Lecture Notes in Artificial Intelligence and Lecture Notes in Bioinformatics) | G40: https://www.scopus.com/inward/record.uri?eid=2-s2.0-85130341946&doi=10.1007%2f978-3-031-02375-0_30&partnerID=40&md5=831c755d4dbb4c7cc508c6f867ed7cc8 | I40: Comparing Facial Expression Recognition in Humans and Machines: Using CAM, Grad-CAM, and Extremal Perturbation | J40: 10.1007/978-3-031-02375-0_30 | M40: Comparing Facial Expression Recognition in Humans and Machines: Using CAM, Grad-CAM, and Extremal Perturbation | N40: AffectNet dataset | O40: https://paperswithcode.com/dataset/affectnet | P40: |DNN| | Q40: |CAM|, |Grad-CAM| | R40: Accuracy | S40: .
...

Sheet 3 Eligibility
A1: Name of Database | B1: Reference Type | C1: Author | D1: Year | E1: Title | F1: Secondary Title | G1: Volume | H1: Number | I1: Pages | J1: Publisher | K1: Place Published | L1: URL | M1: DOI | N1: Keywords | O1: Abstract | P1: Relevence 0,1,0.5 | Q1: Methodology 0, 1, 0.5 | R1: Limitations 0,1,0.5 | S1: Findings 0,1,0.5 | T1: Total
A2: IEEE Xplore | B2: Conference Proceedings | C2: A. Bhat; A. Raychowdhury | D2: 2023 | E2: Reducing Overhead of Feature Importance Visualization via Static GradCAM Computation | F2: 2023 IEEE 5th International Conference on Artificial Intelligence Circuits and Systems (AICAS) | I2: 45413 | M2: 10.1109/AICAS57966.2023.10168594 | N2: Visualization_x000D_ Schedules_x000D_ Runtime_x000D_ Processor scheduling_x000D_ Computational modeling_x000D_ Software algorithms_x000D_ Inference algorithms_x000D_ Convolutional Neural Network (CNN)_x000D_ Explainable AI (XAI)_x000D_ Feature Attribution_x000D_ GradCAM_x000D_ FPGA_x000D_ High Level Synthesis (HLS)_x000D_ Domain Specific Hardware Accelerator | O2: Explainable AI (XAI) methods provide insights into the operation of black-box Deep Neural Network (DNN) models. GradCAM, an XAI algorithm, provides an explanation by highlighting regions in the input feature space that were relevant to the model’s output. It involves a gradient computation step that adds a significant overhead compared to inference and hinders providing explanations to end-users. In this work, we identify the root cause of the problem to be the dynamic run-time automatic differentiation. To overcome this issue, we propose to offload the gradient computation step to compile time via analytic evaluation. We validate the idea by designing an FPGA implementation of GradCAM that schedules the entire computation graph statically. For a TinyML ResNet18 model, we achieve a reduction in the explanation generation overhead from > 2× using software frameworks on CPU/GPU systems to < 0.01× on the FPGA using our designed hardware and static scheduling. | P2: 1 | Q2: 1 | R2: 0.5 | S2: 1 | T2: =SUM(Table145[[#This Row],[Relevence 0,1,0.5]:[Findings 0,1,0.5]]) -> 3.5
A3: IEEE Xplore | B3: Conference Proceedings | C3: S. Chakraborty; K. Kumar; B. P. Reddy; T. Meena; S. Roy | D3: 2023 | E3: An Explainable AI based Clinical Assistance Model for Identifying Patients with the Onset of Sepsis | F3: 2023 IEEE 24th International Conference on Information Reuse and Integration for Data Science (IRI) | I3: 297-302 | M3: 10.1109/IRI58017.2023.00059 | N3: Sensitivity_x000D_ Biological system modeling_x000D_ Predictive models_x000D_ Data science_x000D_ Sepsis_x000D_ Feature extraction_x000D_ Rough surfaces_x000D_ Healthcare_x000D_ XAI_x000D_ Sepsis Prediction_x000D_ Autoencoders | O3: The high mortality rate of sepsis, especially in Intensive Care Unit (ICU) makes it third-highest mortality disease globally. The treatment of sepsis is also time consuming and depends on multi-parametric tests, hence early identification of patients with sepsis becomes crucial. The recent rise in the development of Artificial Intelligence (AI) based models, especially in early prediction of sepsis, have improved the patient outcome. However, drawbacks like low sensitivity, use of excess features that leads to overfitting, and lack of interpretability limit their ability to be used in a clinical setting. So, in this research we have developed a smart, explainable and a highly accurate AI based model (called XAutoNet) that provides quick and early prediction of sepsis with a minimal number of features as input. An application based novel convolutional neural network (CNN) based autoencoder is also implemented that improves the performance of XAutoNet by dimensional reduction. Finally, to unbox the “Black Box” nature of these models, Gradient based Class Activation Map (GradCAM) and SHapley Additive exPlanations (SHAP) are implemented to provide interpretability of autoencoder and XAutoNet in the form of visualization graphs to assist clinicians in diagnosis and treatment. | P3: 0 | Q3: 0 | R3: 0.5 | S3: 1 | T3: =SUM(Table145[[#This Row],[Relevence 0,1,0.5]:[Findings 0,1,0.5]]) -> 1.5
A4: IEEE Xplore | B4: Conference Proceedings | C4: E. Ennadifi; S. Laraba; D. Vincke; B. Mercatoris; B. Gosselin | D4: 2020 | E4: Wheat Diseases Classification and Localization Using Convolutional Neural Networks and GradCAM Visualization | F4: 2020 International Conference on Intelligent Systems and Computer Vision (ISCV) | I4: 45413 | M4: 10.1109/ISCV49265.2020.9204258 | N4: Diseases_x000D_ Agriculture_x000D_ Task analysis_x000D_ Image segmentation_x000D_ Convolutional neural networks_x000D_ Machine learning_x000D_ Databases_x000D_ GradCAM_x000D_ Mask R-CNN_x000D_ image processing_x000D_ classification_x000D_ deep learning_x000D_ plant diseases detection | O4: The world has been witnessing a population boom that has several implications including food security. Wheat is one of the world's most important crops in terms of production and consumption, and demand for it is increasing. On the other hand, diseases can damage the abundance and the quality of the crop, so this needs to be revealed through advanced methods. In recent years, along with the various technological developments, using Convolutional Neural Networks (CNN) has proved to be showing great results in many image classification tasks. However, deep learning models are generally considered as black boxes and it is difficult to understand what the model has learned. The purpose of this article is to detect diseases from wheat images using CNNs and to use visualization methods to understand what these models have learned. For this reason, a wheat database has been collected by CRA-W (Walloon Agricultural Research Center), which contains 1163 images and is classified into two groups namely sick and healthy. Moreover, we propose to use the mask R-CNN for segmentation and extraction of wheat spikes from the background. Furthermore, a visualization and interpretation method, namely Gradient-weighted Class Activation Mapping (GradCAM), is used to locate the disease on the wheat spikes in a non-supervised way. GradCAM is actually used generally to highlight the most important regions from the CNN model's viewpoint that are used to perform the classification. | P4: 1 | Q4: 1 | R4: 1 | S4: 1 | T4: =SUM(Table145[[#This Row],[Relevence 0,1,0.5]:[Findings 0,1,0.5]]) -> 4
A5: IEEE Xplore | B5: Conference Proceedings | C5: R. Golash; U. Gupta; V. Vats; K. Sharma; K. Golash | D5: 2023 | E5: Unveiling the Opacity: Exploring Rationality and Explainability in Tomato Disease Classification | F5: 2023 Second International Conference On Smart Technologies For Smart Nation (SmartTechCon) | I5: 462-468 | M5: 10.1109/SmartTechCon57526.2023.10391741 | N5: Visualization_x000D_ Biological system modeling_x000D_ Crops_x000D_ Closed box_x000D_ Production_x000D_ Transformers_x000D_ Prediction algorithms_x000D_ Explainable AI_x000D_ Tomato Leaf Disease_x000D_ Classification_x000D_ Vision Transformers_x000D_ EfficientNet-B7_x000D_ ResNet101_x000D_ Integrated Gradient_x000D_ GradCAM | O5: Artificial Intelligence has advanced expeditiously over the past years and led to the production of highly complex and leading-edge models deployed to solve problems in a challenging environment. With high dependence on the machine made predictions, it has now become a necessity to be able to look transparently across the black-box and understand the features that influence it’s ability to make decisions. The paper contributes in understanding the rationality and explainability of the models in the classification of diseases in tomato fruit plants. We employed three models, Resnet101, EfficientNetB7, Vision Transformer (vit_base_patch16_224) to classify the disease present in tomato leaf. The opacity of these models are deciphered by implementing two Explainable Artificial Intelligence(XAI) methods, GuidedGradCAM and Integrated Gradients. The explainable algorithms help in unveiling and analyzing the factor that affects the prediction. According to the experimental results, EfficientNet-B7 demonstrates an exceptional level of accuracy, reaching a staggering 99.84% and classifies the disease based on the lesions. The Resnet101 also achieves a significant accuracy of 95.23%, whereas the vision transformer is able to achieve an accuracy of 77.76% only. The paper visualizes and draws a comparison between the two CNN-based models by evaluating their performance based on their validation loss and and accuracy. Interpreting the model’s intelligibility would help in strengthening the practitioner’s trust with the machine-driven decisions and ensure early detection and classification of the disease which would help in taking appropriate measures to prevent substantial crop and economical loss. | P5: 1 | Q5: 1 | R5: 0.5 | S5: 1 | T5: =SUM(Table145[[#This Row],[Relevence 0,1,0.5]:[Findings 0,1,0.5]]) -> 3.5
A6: IEEE Xplore | B6: Conference Proceedings | C6: Y. Hirose; S. Ono | D6: 2023 | E6: Black-box Adversarial Attack against Visual Interpreters for Deep Neural Networks | F6: 2023 18th International Conference on Machine Vision and Applications (MVA) | I6: 45444 | M6: 10.23919/MVA57639.2023.10215758 | N6: Adaptation models_x000D_ Visualization_x000D_ Perturbation methods_x000D_ Machine vision_x000D_ Closed box_x000D_ Artificial neural networks_x000D_ Predictive models | O6: With the rapid development of deep neural networks (DNNs), eXplainable AI, which provides a basis for prediction on inputs, has become increasingly important. In addition, DNNs have a vulnerability called an Adversarial Example (AE), which can cause incorrect output by applying special perturbations to inputs. Potential vulnerabilities can also exist in image interpreters such as GradCAM, necessitating their investigation, as these vulnerabilities could potentially result in misdiagnosis within medical imaging. Therefore, this study proposes a black-box adversarial attack method that misleads the image interpreter using Sep-CMA-ES. The proposed method deceptively shifts the focus area of the image interpreter to a different location from that of the original image while maintaining the same predictive labels. | P6: 0 | Q6: 1 | R6: 0.5 | S6: 0.5 | T6: =SUM(Table145[[#This Row],[Relevence 0,1,0.5]:[Findings 0,1,0.5]]) -> 2
A7: IEEE Xplore | B7: Conference Proceedings | C7: S. M. Javali; R. S. Upadhyayula; T. De | D7: 2022 | E7: Comparative study of xAI layer-wise algorithms with a Robust Recommendation framework of Inductive Clustering for Polyp Segmentation and Classification | F7: 2021 International Seminar on Machine Learning, Optimization, and Data Science (ISMODE) | I7: 325-330 | M7: 10.1109/ISMODE53584.2022.9743003 | N7: Deep learning_x000D_ Training_x000D_ Analytical models_x000D_ Visualization_x000D_ Computational modeling_x000D_ Predictive models_x000D_ Prediction algorithms_x000D_ eXplainable Artificial Intelligence (xAI)_x000D_ colorectal cancer_x000D_ polyp segmentation_x000D_ inductive clustering_x000D_ image matching_x000D_ Feature Pyramid Network (FPN) | O7: Explainable Artificial Intelligence (xAI) is aimed at unboxing the AI model choices by providing interpretable explanations mitigating the black-box nature of algorithms and improving the transparency. Availability of many xAI techniques for medical imaging studies, necessitates a need to understand and pick a suitable approach for different stakeholders (clinician/patient). Interpretation of model predictions could be benefitted by comparing different xAI approaches. We explored different xAI techniques on Kvasir-SEG polyp segmentation dataset. A comparative analysis of attributions from convolutional layers of Feature Pyramid Network (FPN) model (Dice coefficient = 0.942 and meanIOU = 0.916) is provided. We observed that Layered GradCAM provides a very robust visual trajectory of explanations flowing through encoder-decoder-segmentation blocks. We investigated an explanation-by-example approach wherein we compare and match the predicted mask with key-point features from the training corpus. In addition, we have developed a recommendation approach using Inductive Clustering for classifying predicted polyps based on their size and area into three classes – small, medium and large. The recommendation could assist in prioritizing the patient check-up and subsequent timely intervention by a clinician. | P7: 0 | Q7: 1 | R7: 0.5 | S7: 0.5 | T7: =SUM(Table145[[#This Row],[Relevence 0,1,0.5]:[Findings 0,1,0.5]]) -> 2
A8: IEEE Xplore | B8: Conference Proceedings | C8: S. Kusunose; Y. Shinomiya; T. Ushiwaka; N. Maeda; Y. Hoshino | D8: 2021 | E8: Improving Individually Selectness for Immune Cells using GradCAM | F8: 2021 5th IEEE International Conference on Cybernetics (CYBCONF) | I8: 034-038 | M8: 10.1109/CYBCONF51991.2021.9464134 | N8: Image recognition_x000D_ Shape_x000D_ Conferences_x000D_ Focusing_x000D_ Feature extraction_x000D_ Proposals_x000D_ Medical diagnostic imaging_x000D_ Deep Learning_x000D_ Immune Cell_x000D_ GradCAM_x000D_ Image Processing | O8: This paper focuses on the analysis of behavior of immune cells for supporting diagnosis. The previous work has proposed to detect immune cells from medical images by recognition frequency space. However, the work has a problem that selects a region including multiple cells as a single cell. This paper aims to relax the problem by focusing the locality of cell shapes. Our proposal uses gradient-weighted class activation mapping (GradCAM) to capture locality characteristics of immune cells. The results shows that the densely inhabited immune cells are correctly selected. Our proposal has some issues that a cell is occasionally detected as multiple ones. We consider that this issue is can be solved by image processing techniques such as non-maximum suppression. | P8: 1 | Q8: 1 | R8: 1 | S8: 1 | T8: =SUM(Table145[[#This Row],[Relevence 0,1,0.5]:[Findings 0,1,0.5]]) -> 4
A9: IEEE Xplore | B9: Conference Proceedings | C9: J. Maximino; M. Coimbra; J. Pedrosa | D9: 2022 | E9: Detection of COVID-19 in Point of Care Lung Ultrasound | F9: 2022 44th Annual International Conference of the IEEE Engineering in Medicine & Biology Society (EMBC) | I9: 1527-1530 | M9: 10.1109/EMBC48229.2022.9871235 | N9: COVID-19_x000D_ Training_x000D_ Ultrasonic imaging_x000D_ Point of care_x000D_ Lung_x000D_ Computer architecture_x000D_ Data models | O9: The coronavirus disease 2019 (COVID-19) evolved into a global pandemic, responsible for a significant number of infections and deaths. In this scenario, point-of-care ultrasound (POCUS) has emerged as a viable and safe imaging modality. Computer vision (CV) solutions have been proposed to aid clinicians in POCUS image interpretation, namely detection/segmentation of structures and image/patient classification but relevant challenges still remain. As such, the aim of this study is to develop CV algorithms, using Deep Learning techniques, to create tools that can aid doctors in the diagnosis of viral and bacterial pneumonia (VP and BP) through POCUS exams. To do so, convolutional neural networks were designed to perform in classification tasks. The architectures chosen to build these models were the VGG16, ResNet50, DenseNet169 e MobileNetV2. Patients images were divided in three classes: healthy (HE), BP and VP (which includes COVID-19). Through a comparative study, which was based on several performance metrics, the model based on the DenseNet169 architecture was designated as the best performing model, achieving 78% average accuracy value of the five iterations of 5- Fold Cross-Validation. Given that the currently available POCUS datasets for COVID-19 are still limited, the training of the models was negatively affected by such and the models were not tested in an independent dataset. Furthermore, it was also not possible to perform lesion detection tasks. Nonetheless, in order to provide explainability and understanding of the models, Gradient-weighted Class Activation Mapping (GradCAM) were used as a tool to highlight the most relevant classification regions. Clinical relevance – Reveals the potential of POCUS to support COVID-19 screening. The results are very promising although the dataset is limite | P9: 1 | Q9: 1 | R9: 1 | S9: 1 | T9: =SUM(Table145[[#This Row],[Relevence 0,1,0.5]:[Findings 0,1,0.5]]) -> 4
A10: IEEE Xplore | B10: Journal Article | C10: T. Meena; K. Sarawadekar | D10: 2024 | E10: An eXplainable Self-Attention-Based Spatial–Temporal Analysis for Human Activity Recognition | F10: IEEE Sensors Journal | G10: 24 | H10: 1 | I10: 635-644 | M10: 10.1109/JSEN.2023.3335449 | N10: Sensors_x000D_ Feature extraction_x000D_ Human activity recognition_x000D_ Convolutional neural networks_x000D_ Computer architecture_x000D_ Biomedical monitoring_x000D_ Computational modeling_x000D_ 1-D gradient-weighted class activation mapping (GradCAM)_x000D_ explainability_x000D_ human activity recognition (HAR)_x000D_ long short-term memory (LSTM)_x000D_ self-attention_x000D_ smartphones | O10: Human activity recognition (HAR) from inertial sensors has been a hot topic of research in recent years. Recognition of human activities from smartphone sensors poses a significant challenge because of the complexity of sensor data. In this work, a novel self-attention convolutional neural network-long short-term memory (CNN-LSTM) module is proposed by using the sensor data from inbuilt inertial sensors in smartphones. The experiment includes the results on the well-known HAR public datasets, namely, University of California HAR Dataset (UCI-HAR), University of California Human Activities and Postural Transitions (UCI-HAPT), and Sanitation datasets. The performance evaluation of the proposed model confirmed its effectiveness, as it achieved high accuracy rates across all tested datasets. Furthermore, ablation studies performed on the depth and number of hyperparameters used in the model demonstrate its effectiveness in achieving higher classification accuracy. The model was also evaluated using other metrics and was found to be cost effective in terms of the number of floating-point operations per second (FLOPs). In addition, a 1-D gradient-weighted class activation mapping (GradCAM) was implemented on the self-attention layer of the proposed model to determine and visualize the features responsible for the predicted activities. Our proposed model demonstrated superior performance on each individual dataset and achieved the best results on the UCI-HAR dataset. Specifically, for the UCI-HAR dataset, our model achieved an accuracy score of 0.9829, precision of 0.9833, recall of 0.9840, and ${F}1$ score of 0.9836 on the test data. Furthermore, the Matthews correlation coefficient (MCC) and Kappa score were calculated as 0.9795 and 0.9794, respectively. | P10: 0 | Q10: 0 | R10: 0.5 | S10: 1 | T10: =SUM(Table145[[#This Row],[Relevence 0,1,0.5]:[Findings 0,1,0.5]]) -> 1.5
